<?xml version="1.0"?>
<robot name="gripper_v1">

  <!-- ################################################################################################# -->
  <!-- Base Link -->
  <link name="base_link">
    <visual>
      <geometry>
        <cylinder radius="0.5" length="0.05"/>
      </geometry>
      <material name="White"/>
    </visual>
    <collision>
      <geometry>
        <cylinder radius="0.5" length="0.05"/>
      </geometry>
      <material name="White"/>
    </collision>
    <inertial>
      <mass value="1.0"/>
      <origin xyz="0 0 0"/>
      <inertia ixx="0.01" ixy="0" ixz="0" iyy="0.01" iyz="0" izz="0.01"/>
    </inertial>
  </link>

  <!-- ################################################################################################# -->
  <!-- Link 1-->
  <link name="link_1">
    <visual>
      <geometry>
        <cylinder radius="0.125" length="0.5"/>
      </geometry>
      <material name="Blue"/>
    </visual>
    <collision>
      <geometry>
        <cylinder radius="0.125" length="0.5"/>
      </geometry>
      <material name="Blue"/>
    </collision>
    <inertial>
      <mass value="1.0"/>
      <origin xyz="0 0 0"/>
      <inertia ixx="0.01" ixy="0" ixz="0" iyy="0.01" iyz="0" izz="0.01"/>
    </inertial>
  </link>

  <!-- Joint 1-->
  <joint name="joint_1" type="revolute">
    <parent link="base_link"/>
    <child link="link_1"/>
    <origin xyz="0 0 0.275" rpy="0 0 0"/>
    <axis xyz="0 1 0"/>
    <limit effort="10" lower="-1.57" upper="1.57" velocity="5"/>
  </joint>

  <!-- ################################################################################################# -->
  <!-- Link 2-->
  <link name="link_2">
    <visual>
      <geometry>
        <box size="0.5 0.2 0.2"/>
      </geometry>
      <material name="Red"/>
    </visual>
    <collision>
      <geometry>
        <box size="0.5 0.2 0.2"/>
      </geometry>
      <material name="Blue"/>
    </collision>
    <inertial>
      <mass value="1.0"/>
      <origin xyz="0 0 0"/>
      <inertia ixx="0.01" ixy="0" ixz="0" iyy="0.01" iyz="0" izz="0.01"/>
    </inertial>
  </link>

  <!-- Joint 2 -->  
  <joint name="joint_2" type="fixed">
    <parent link="link_1"/>
    <child link="link_2"/>
    <origin xyz="0 0 0.35" rpy="0 0 0"/>
  </joint>

  <!-- ################################################################################################# -->
  <!-- Link 3-->
  <link name="link_3">
    <visual>
      <geometry>
        <box size="0.2 0.2 0.5"/>
      </geometry>
      <material name="Red"/>
    </visual>
    <collision>
      <geometry>
        <box size="0.2 0.2 0.5"/>
      </geometry>
      <material name="Blue"/>
    </collision>
    <inertial>
      <mass value="1.0"/>
      <origin xyz="0 0 0"/>
      <inertia ixx="0.01" ixy="0" ixz="0" iyy="0.01" iyz="0" izz="0.01"/>
    </inertial>
  </link>

  <!-- Joint 3 -->  
  <joint name="joint_3" type="revolute">
    <parent link="link_2"/>
    <child link="link_3"/>
    <origin xyz="0.5 0 0.2" rpy="0 0.785 0"/>
    <axis xyz="0 1 0"/>
    <limit effort="10" lower="-1.57" upper="1.57" velocity="5"/>
  </joint>

  <!-- Link 4-->
  <link name="link_4">
    <visual>
      <geometry>
        <box size="0.2 0.2 0.5"/>
      </geometry>
      <material name="Red"/>
    </visual>
    <collision>
      <geometry>
        <box size="0.2 0.2 0.5"/>
      </geometry>
      <material name="Blue"/>
    </collision>
    <inertial>
      <mass value="1.0"/>
      <origin xyz="0 0 0"/>
      <inertia ixx="0.01" ixy="0" ixz="0" iyy="0.01" iyz="0" izz="0.01"/>
    </inertial>
  </link>

  <!-- Joint 4 -->  
  <joint name="joint_4" type="revolute">
    <parent link="link_2"/>
    <child link="link_4"/>
    <origin xyz="-0.5 0 0.2" rpy="0 -0.785 0"/>
    <axis xyz="0 1 0"/>
    <limit effort="10" lower="-1.57" upper="1.57" velocity="5"/>
  </joint>

  <!-- ################################################################################################# -->
  <!-- Link 5-->
  <link name="link_5">
    <visual>
      <geometry>
        <box size="0.2 0.2 0.5"/>
      </geometry>
      <material name="Red"/>
    </visual>
    <collision>
      <geometry>
        <box size="0.2 0.2 0.5"/>
      </geometry>
      <material name="Blue"/>
    </collision>
    <inertial>
      <mass value="1.0"/>
      <origin xyz="0 0 0"/>
      <inertia ixx="0.01" ixy="0" ixz="0" iyy="0.01" iyz="0" izz="0.01"/>
    </inertial>
  </link>

  <!-- Joint 5 -->  
  <joint name="joint_5" type="revolute">
    <parent link="link_3"/>
    <child link="link_5"/>
    <origin xyz="0.5 0 0.2" rpy="0 0.785 0"/>
    <axis xyz="0 1 0"/>
    <limit effort="10" lower="-1.57" upper="1.57" velocity="5"/>
  </joint>

  <!-- Link 6-->
  <link name="link_6">
    <visual>
      <geometry>
        <box size="0.2 0.2 0.5"/>
      </geometry>
      <material name="Red"/>
    </visual>
    <collision>
      <geometry>
        <box size="0.2 0.2 0.5"/>
      </geometry>
      <material name="Blue"/>
    </collision>
    <inertial>
      <mass value="1.0"/>
      <origin xyz="0 0 0"/>
      <inertia ixx="0.01" ixy="0" ixz="0" iyy="0.01" iyz="0" izz="0.01"/>
    </inertial>
  </link>

  <!-- Joint 6 -->  
  <joint name="joint_6" type="revolute">
    <parent link="link_4"/>
    <child link="link_6"/>
    <origin xyz="-0.5 0 0.2" rpy="0 -0.785 0"/>
    <axis xyz="0 1 0"/>
    <limit effort="10" lower="-1.57" upper="1.57" velocity="5"/>
  </joint>


  <!-- ################################################################################################# -->
  <!-- Gazebo plugin for ROS integration -->
  <gazebo>
    <plugin name="gazebo_ros_control" filename="libgazebo_ros_control.so">
      <robotNamespace>/</robotNamespace>
      <controlPeriod>0.001</controlPeriod>
      <robotSimType>gazebo_ros_control/DefaultRobotHWSim</robotSimType>
    </plugin>
  </gazebo>

  <gazebo reference="base_link">
    <material>Gazebo/White</material>
  </gazebo>

  <gazebo reference="link_1">
    <material>Gazebo/Blue</material>
  </gazebo>

  <gazebo reference="link_2">
    <material>Gazebo/Red</material>
  </gazebo>

</robot>
